%load_ext sql

{
 "cells": [
  {
   "cell_type": "code",
   "execution_count": 1,
   "id": "38a5c261-4125-4abc-a311-93bba1ebf9b2",
   "metadata": {},
   "outputs": [
    {
     "name": "stderr",
     "output_type": "stream",
     "text": [
      "\n",
      "[notice] A new release of pip is available: 25.0 -> 25.0.1\n",
      "[notice] To update, run: python.exe -m pip install --upgrade pip\n"
     ]
    },
    {
     "name": "stdout",
     "output_type": "stream",
     "text": [
      "Requirement already satisfied: ipython-sql in c:\\users\\user\\desktop\\python\\.venv\\lib\\site-packages (0.5.0)\n",
      "Requirement already satisfied: prettytable in c:\\users\\user\\desktop\\python\\.venv\\lib\\site-packages (from ipython-sql) (3.14.0)\n",
      "Requirement already satisfied: ipython in c:\\users\\user\\desktop\\python\\.venv\\lib\\site-packages (from ipython-sql) (8.32.0)\n",
      "Requirement already satisfied: sqlalchemy>=2.0 in c:\\users\\user\\desktop\\python\\.venv\\lib\\site-packages (from ipython-sql) (2.0.38)\n",
      "Requirement already satisfied: sqlparse in c:\\users\\user\\desktop\\python\\.venv\\lib\\site-packages (from ipython-sql) (0.5.3)\n",
      "Requirement already satisfied: six in c:\\users\\user\\desktop\\python\\.venv\\lib\\site-packages (from ipython-sql) (1.17.0)\n",
      "Requirement already satisfied: ipython-genutils in c:\\users\\user\\desktop\\python\\.venv\\lib\\site-packages (from ipython-sql) (0.2.0)\n",
      "Requirement already satisfied: greenlet!=0.4.17 in c:\\users\\user\\desktop\\python\\.venv\\lib\\site-packages (from sqlalchemy>=2.0->ipython-sql) (3.1.1)\n",
      "Requirement already satisfied: typing-extensions>=4.6.0 in c:\\users\\user\\desktop\\python\\.venv\\lib\\site-packages (from sqlalchemy>=2.0->ipython-sql) (4.12.2)\n",
      "Requirement already satisfied: colorama in c:\\users\\user\\desktop\\python\\.venv\\lib\\site-packages (from ipython->ipython-sql) (0.4.6)\n",
      "Requirement already satisfied: decorator in c:\\users\\user\\desktop\\python\\.venv\\lib\\site-packages (from ipython->ipython-sql) (5.1.1)\n",
      "Requirement already satisfied: exceptiongroup in c:\\users\\user\\desktop\\python\\.venv\\lib\\site-packages (from ipython->ipython-sql) (1.2.2)\n",
      "Requirement already satisfied: jedi>=0.16 in c:\\users\\user\\desktop\\python\\.venv\\lib\\site-packages (from ipython->ipython-sql) (0.19.2)\n",
      "Requirement already satisfied: matplotlib-inline in c:\\users\\user\\desktop\\python\\.venv\\lib\\site-packages (from ipython->ipython-sql) (0.1.7)\n",
      "Requirement already satisfied: prompt_toolkit<3.1.0,>=3.0.41 in c:\\users\\user\\desktop\\python\\.venv\\lib\\site-packages (from ipython->ipython-sql) (3.0.50)\n",
      "Requirement already satisfied: pygments>=2.4.0 in c:\\users\\user\\desktop\\python\\.venv\\lib\\site-packages (from ipython->ipython-sql) (2.19.1)\n",
      "Requirement already satisfied: stack_data in c:\\users\\user\\desktop\\python\\.venv\\lib\\site-packages (from ipython->ipython-sql) (0.6.3)\n",
      "Requirement already satisfied: traitlets>=5.13.0 in c:\\users\\user\\desktop\\python\\.venv\\lib\\site-packages (from ipython->ipython-sql) (5.14.3)\n",
      "Requirement already satisfied: wcwidth in c:\\users\\user\\desktop\\python\\.venv\\lib\\site-packages (from prettytable->ipython-sql) (0.2.13)\n",
      "Requirement already satisfied: parso<0.9.0,>=0.8.4 in c:\\users\\user\\desktop\\python\\.venv\\lib\\site-packages (from jedi>=0.16->ipython->ipython-sql) (0.8.4)\n",
      "Requirement already satisfied: executing>=1.2.0 in c:\\users\\user\\desktop\\python\\.venv\\lib\\site-packages (from stack_data->ipython->ipython-sql) (2.2.0)\n",
      "Requirement already satisfied: asttokens>=2.1.0 in c:\\users\\user\\desktop\\python\\.venv\\lib\\site-packages (from stack_data->ipython->ipython-sql) (3.0.0)\n",
      "Requirement already satisfied: pure-eval in c:\\users\\user\\desktop\\python\\.venv\\lib\\site-packages (from stack_data->ipython->ipython-sql) (0.2.3)\n",
      "(sqlite3.OperationalError) near \"21\": syntax error\n",
      "[SQL: 21 Darbas su SQLAlchemy ir Python/mokykla.db]\n",
      "(Background on this error at: https://sqlalche.me/e/20/e3q8)\n"
     ]
    }
   ],
   "source": [
    "!pip install ipython-sql\n",
    "%load_ext sql\n",
    "%sql sqlite:///C:/Users/User/Desktop/PYTHON/Pamoka 21 Darbas su SQLAlchemy ir Python/mokykla.db\n"
   ]
  },
  {
   "cell_type": "code",
   "execution_count": 2,
   "id": "0b850b00-5f73-4bf5-888a-0b8260784bc5",
   "metadata": {},
   "outputs": [
    {
     "ename": "SyntaxError",
     "evalue": "invalid syntax (2078879528.py, line 1)",
     "output_type": "error",
     "traceback": [
      "\u001b[1;36m  Cell \u001b[1;32mIn[2], line 1\u001b[1;36m\u001b[0m\n\u001b[1;33m    $pip install ipython-sql\u001b[0m\n\u001b[1;37m    ^\u001b[0m\n\u001b[1;31mSyntaxError\u001b[0m\u001b[1;31m:\u001b[0m invalid syntax\n"
     ]
    }
   ],
   "source": [
    "$pip install ipython-sql\n",
    "%load_ext sql\n",
    "%sql sqlite:///C:/Users/User/Desktop/PYTHON/Pamoka 21 Darbas su SQLAlchemy ir Python/mokykla.db"
   ]
  },
  {
   "cell_type": "code",
   "execution_count": 3,
   "id": "2e2d0625-d4b9-4c0f-92e5-61ccf455f47c",
   "metadata": {},
   "outputs": [
    {
     "name": "stdout",
     "output_type": "stream",
     "text": [
      "Requirement already satisfied: ipython-sql in c:\\users\\user\\desktop\\python\\.venv\\lib\\site-packages (0.5.0)\n",
      "Requirement already satisfied: prettytable in c:\\users\\user\\desktop\\python\\.venv\\lib\\site-packages (from ipython-sql) (3.14.0)\n",
      "Requirement already satisfied: ipython in c:\\users\\user\\desktop\\python\\.venv\\lib\\site-packages (from ipython-sql) (8.32.0)\n",
      "Requirement already satisfied: sqlalchemy>=2.0 in c:\\users\\user\\desktop\\python\\.venv\\lib\\site-packages (from ipython-sql) (2.0.38)\n",
      "Requirement already satisfied: sqlparse in c:\\users\\user\\desktop\\python\\.venv\\lib\\site-packages (from ipython-sql) (0.5.3)\n",
      "Requirement already satisfied: six in c:\\users\\user\\desktop\\python\\.venv\\lib\\site-packages (from ipython-sql) (1.17.0)\n",
      "Requirement already satisfied: ipython-genutils in c:\\users\\user\\desktop\\python\\.venv\\lib\\site-packages (from ipython-sql) (0.2.0)\n",
      "Requirement already satisfied: greenlet!=0.4.17 in c:\\users\\user\\desktop\\python\\.venv\\lib\\site-packages (from sqlalchemy>=2.0->ipython-sql) (3.1.1)\n",
      "Requirement already satisfied: typing-extensions>=4.6.0 in c:\\users\\user\\desktop\\python\\.venv\\lib\\site-packages (from sqlalchemy>=2.0->ipython-sql) (4.12.2)\n",
      "Requirement already satisfied: colorama in c:\\users\\user\\desktop\\python\\.venv\\lib\\site-packages (from ipython->ipython-sql) (0.4.6)\n",
      "Requirement already satisfied: decorator in c:\\users\\user\\desktop\\python\\.venv\\lib\\site-packages (from ipython->ipython-sql) (5.1.1)\n",
      "Requirement already satisfied: exceptiongroup in c:\\users\\user\\desktop\\python\\.venv\\lib\\site-packages (from ipython->ipython-sql) (1.2.2)\n",
      "Requirement already satisfied: jedi>=0.16 in c:\\users\\user\\desktop\\python\\.venv\\lib\\site-packages (from ipython->ipython-sql) (0.19.2)\n",
      "Requirement already satisfied: matplotlib-inline in c:\\users\\user\\desktop\\python\\.venv\\lib\\site-packages (from ipython->ipython-sql) (0.1.7)\n",
      "Requirement already satisfied: prompt_toolkit<3.1.0,>=3.0.41 in c:\\users\\user\\desktop\\python\\.venv\\lib\\site-packages (from ipython->ipython-sql) (3.0.50)\n",
      "Requirement already satisfied: pygments>=2.4.0 in c:\\users\\user\\desktop\\python\\.venv\\lib\\site-packages (from ipython->ipython-sql) (2.19.1)\n",
      "Requirement already satisfied: stack_data in c:\\users\\user\\desktop\\python\\.venv\\lib\\site-packages (from ipython->ipython-sql) (0.6.3)\n",
      "Requirement already satisfied: traitlets>=5.13.0 in c:\\users\\user\\desktop\\python\\.venv\\lib\\site-packages (from ipython->ipython-sql) (5.14.3)\n",
      "Requirement already satisfied: wcwidth in c:\\users\\user\\desktop\\python\\.venv\\lib\\site-packages (from prettytable->ipython-sql) (0.2.13)\n",
      "Requirement already satisfied: parso<0.9.0,>=0.8.4 in c:\\users\\user\\desktop\\python\\.venv\\lib\\site-packages (from jedi>=0.16->ipython->ipython-sql) (0.8.4)\n",
      "Requirement already satisfied: executing>=1.2.0 in c:\\users\\user\\desktop\\python\\.venv\\lib\\site-packages (from stack_data->ipython->ipython-sql) (2.2.0)\n",
      "Requirement already satisfied: asttokens>=2.1.0 in c:\\users\\user\\desktop\\python\\.venv\\lib\\site-packages (from stack_data->ipython->ipython-sql) (3.0.0)\n",
      "Requirement already satisfied: pure-eval in c:\\users\\user\\desktop\\python\\.venv\\lib\\site-packages (from stack_data->ipython->ipython-sql) (0.2.3)\n"
     ]
    },
    {
     "name": "stderr",
     "output_type": "stream",
     "text": [
      "\n",
      "[notice] A new release of pip is available: 25.0 -> 25.0.1\n",
      "[notice] To update, run: python.exe -m pip install --upgrade pip\n"
     ]
    }
   ],
   "source": [
    "!pip install ipython-sql\n"
   ]
  },
  {
   "cell_type": "code",
   "execution_count": 4,
   "id": "04f7bb85-96a6-4f57-81e0-f6259698ebbe",
   "metadata": {},
   "outputs": [
    {
     "name": "stdout",
     "output_type": "stream",
     "text": [
      "The sql extension is already loaded. To reload it, use:\n",
      "  %reload_ext sql\n",
      "(sqlite3.OperationalError) near \"21\": syntax error\n",
      "[SQL: 21 Darbas su SQLAlchemy ir Python/mokykla.db]\n",
      "(Background on this error at: https://sqlalche.me/e/20/e3q8)\n"
     ]
    }
   ],
   "source": [
    "%load_ext sql\n",
    "%sql sqlite:///C:/Users/User/Desktop/PYTHON/Pamoka 21 Darbas su SQLAlchemy ir Python/mokykla.db\n"
   ]
  },
  {
   "cell_type": "code",
   "execution_count": 5,
   "id": "1d25b856-e21c-4190-b277-c8536d11f136",
   "metadata": {},
   "outputs": [
    {
     "name": "stdout",
     "output_type": "stream",
     "text": [
      "Traceback (most recent call last):\n",
      "  File \"C:\\Users\\User\\Desktop\\PYTHON\\.venv\\lib\\site-packages\\sqlalchemy\\engine\\base.py\", line 146, in __init__\n",
      "    self._dbapi_connection = engine.raw_connection()\n",
      "  File \"C:\\Users\\User\\Desktop\\PYTHON\\.venv\\lib\\site-packages\\sqlalchemy\\engine\\base.py\", line 3298, in raw_connection\n",
      "    return self.pool.connect()\n",
      "  File \"C:\\Users\\User\\Desktop\\PYTHON\\.venv\\lib\\site-packages\\sqlalchemy\\pool\\base.py\", line 449, in connect\n",
      "    return _ConnectionFairy._checkout(self)\n",
      "  File \"C:\\Users\\User\\Desktop\\PYTHON\\.venv\\lib\\site-packages\\sqlalchemy\\pool\\base.py\", line 1263, in _checkout\n",
      "    fairy = _ConnectionRecord.checkout(pool)\n",
      "  File \"C:\\Users\\User\\Desktop\\PYTHON\\.venv\\lib\\site-packages\\sqlalchemy\\pool\\base.py\", line 712, in checkout\n",
      "    rec = pool._do_get()\n",
      "  File \"C:\\Users\\User\\Desktop\\PYTHON\\.venv\\lib\\site-packages\\sqlalchemy\\pool\\impl.py\", line 179, in _do_get\n",
      "    with util.safe_reraise():\n",
      "  File \"C:\\Users\\User\\Desktop\\PYTHON\\.venv\\lib\\site-packages\\sqlalchemy\\util\\langhelpers.py\", line 146, in __exit__\n",
      "    raise exc_value.with_traceback(exc_tb)\n",
      "  File \"C:\\Users\\User\\Desktop\\PYTHON\\.venv\\lib\\site-packages\\sqlalchemy\\pool\\impl.py\", line 177, in _do_get\n",
      "    return self._create_connection()\n",
      "  File \"C:\\Users\\User\\Desktop\\PYTHON\\.venv\\lib\\site-packages\\sqlalchemy\\pool\\base.py\", line 390, in _create_connection\n",
      "    return _ConnectionRecord(self)\n",
      "  File \"C:\\Users\\User\\Desktop\\PYTHON\\.venv\\lib\\site-packages\\sqlalchemy\\pool\\base.py\", line 674, in __init__\n",
      "    self.__connect()\n",
      "  File \"C:\\Users\\User\\Desktop\\PYTHON\\.venv\\lib\\site-packages\\sqlalchemy\\pool\\base.py\", line 900, in __connect\n",
      "    with util.safe_reraise():\n",
      "  File \"C:\\Users\\User\\Desktop\\PYTHON\\.venv\\lib\\site-packages\\sqlalchemy\\util\\langhelpers.py\", line 146, in __exit__\n",
      "    raise exc_value.with_traceback(exc_tb)\n",
      "  File \"C:\\Users\\User\\Desktop\\PYTHON\\.venv\\lib\\site-packages\\sqlalchemy\\pool\\base.py\", line 896, in __connect\n",
      "    self.dbapi_connection = connection = pool._invoke_creator(self)\n",
      "  File \"C:\\Users\\User\\Desktop\\PYTHON\\.venv\\lib\\site-packages\\sqlalchemy\\engine\\create.py\", line 646, in connect\n",
      "    return dialect.connect(*cargs, **cparams)\n",
      "  File \"C:\\Users\\User\\Desktop\\PYTHON\\.venv\\lib\\site-packages\\sqlalchemy\\engine\\default.py\", line 622, in connect\n",
      "    return self.loaded_dbapi.connect(*cargs, **cparams)\n",
      "sqlite3.OperationalError: unable to open database file\n",
      "\n",
      "The above exception was the direct cause of the following exception:\n",
      "\n",
      "Traceback (most recent call last):\n",
      "  File \"C:\\Users\\User\\Desktop\\PYTHON\\.venv\\lib\\site-packages\\sql\\magic.py\", line 196, in execute\n",
      "    conn = sql.connection.Connection.set(\n",
      "  File \"C:\\Users\\User\\Desktop\\PYTHON\\.venv\\lib\\site-packages\\sql\\connection.py\", line 70, in set\n",
      "    cls.current = existing or Connection(descriptor, connect_args, creator)\n",
      "  File \"C:\\Users\\User\\Desktop\\PYTHON\\.venv\\lib\\site-packages\\sql\\connection.py\", line 55, in __init__\n",
      "    self.internal_connection = engine.connect()\n",
      "  File \"C:\\Users\\User\\Desktop\\PYTHON\\.venv\\lib\\site-packages\\sqlalchemy\\engine\\base.py\", line 3274, in connect\n",
      "    return self._connection_cls(self)\n",
      "  File \"C:\\Users\\User\\Desktop\\PYTHON\\.venv\\lib\\site-packages\\sqlalchemy\\engine\\base.py\", line 148, in __init__\n",
      "    Connection._handle_dbapi_exception_noconnection(\n",
      "  File \"C:\\Users\\User\\Desktop\\PYTHON\\.venv\\lib\\site-packages\\sqlalchemy\\engine\\base.py\", line 2439, in _handle_dbapi_exception_noconnection\n",
      "    raise sqlalchemy_exception.with_traceback(exc_info[2]) from e\n",
      "  File \"C:\\Users\\User\\Desktop\\PYTHON\\.venv\\lib\\site-packages\\sqlalchemy\\engine\\base.py\", line 146, in __init__\n",
      "    self._dbapi_connection = engine.raw_connection()\n",
      "  File \"C:\\Users\\User\\Desktop\\PYTHON\\.venv\\lib\\site-packages\\sqlalchemy\\engine\\base.py\", line 3298, in raw_connection\n",
      "    return self.pool.connect()\n",
      "  File \"C:\\Users\\User\\Desktop\\PYTHON\\.venv\\lib\\site-packages\\sqlalchemy\\pool\\base.py\", line 449, in connect\n",
      "    return _ConnectionFairy._checkout(self)\n",
      "  File \"C:\\Users\\User\\Desktop\\PYTHON\\.venv\\lib\\site-packages\\sqlalchemy\\pool\\base.py\", line 1263, in _checkout\n",
      "    fairy = _ConnectionRecord.checkout(pool)\n",
      "  File \"C:\\Users\\User\\Desktop\\PYTHON\\.venv\\lib\\site-packages\\sqlalchemy\\pool\\base.py\", line 712, in checkout\n",
      "    rec = pool._do_get()\n",
      "  File \"C:\\Users\\User\\Desktop\\PYTHON\\.venv\\lib\\site-packages\\sqlalchemy\\pool\\impl.py\", line 179, in _do_get\n",
      "    with util.safe_reraise():\n",
      "  File \"C:\\Users\\User\\Desktop\\PYTHON\\.venv\\lib\\site-packages\\sqlalchemy\\util\\langhelpers.py\", line 146, in __exit__\n",
      "    raise exc_value.with_traceback(exc_tb)\n",
      "  File \"C:\\Users\\User\\Desktop\\PYTHON\\.venv\\lib\\site-packages\\sqlalchemy\\pool\\impl.py\", line 177, in _do_get\n",
      "    return self._create_connection()\n",
      "  File \"C:\\Users\\User\\Desktop\\PYTHON\\.venv\\lib\\site-packages\\sqlalchemy\\pool\\base.py\", line 390, in _create_connection\n",
      "    return _ConnectionRecord(self)\n",
      "  File \"C:\\Users\\User\\Desktop\\PYTHON\\.venv\\lib\\site-packages\\sqlalchemy\\pool\\base.py\", line 674, in __init__\n",
      "    self.__connect()\n",
      "  File \"C:\\Users\\User\\Desktop\\PYTHON\\.venv\\lib\\site-packages\\sqlalchemy\\pool\\base.py\", line 900, in __connect\n",
      "    with util.safe_reraise():\n",
      "  File \"C:\\Users\\User\\Desktop\\PYTHON\\.venv\\lib\\site-packages\\sqlalchemy\\util\\langhelpers.py\", line 146, in __exit__\n",
      "    raise exc_value.with_traceback(exc_tb)\n",
      "  File \"C:\\Users\\User\\Desktop\\PYTHON\\.venv\\lib\\site-packages\\sqlalchemy\\pool\\base.py\", line 896, in __connect\n",
      "    self.dbapi_connection = connection = pool._invoke_creator(self)\n",
      "  File \"C:\\Users\\User\\Desktop\\PYTHON\\.venv\\lib\\site-packages\\sqlalchemy\\engine\\create.py\", line 646, in connect\n",
      "    return dialect.connect(*cargs, **cparams)\n",
      "  File \"C:\\Users\\User\\Desktop\\PYTHON\\.venv\\lib\\site-packages\\sqlalchemy\\engine\\default.py\", line 622, in connect\n",
      "    return self.loaded_dbapi.connect(*cargs, **cparams)\n",
      "sqlalchemy.exc.OperationalError: (sqlite3.OperationalError) unable to open database file\n",
      "(Background on this error at: https://sqlalche.me/e/20/e3q8)\n",
      "\n",
      "Connection info needed in SQLAlchemy format, example:\n",
      "               postgresql://username:password@hostname/dbname\n",
      "               or an existing connection: dict_keys(['sqlite:///C:/Users/User/Desktop/PYTHON/Pamoka'])\n"
     ]
    }
   ],
   "source": [
    "%sql sqlite:///\"C:/Users/User/Desktop/PYTHON/Pamoka 21 Darbas su SQLAlchemy ir Python/mokykla.db\"\n"
   ]
  },
  {
   "cell_type": "code",
   "execution_count": 6,
   "id": "1124b027-5bd6-45ce-b4cb-eea0b5fb3ee0",
   "metadata": {},
   "outputs": [
    {
     "name": "stdout",
     "output_type": "stream",
     "text": [
      "The sql extension is already loaded. To reload it, use:\n",
      "  %reload_ext sql\n"
     ]
    }
   ],
   "source": [
    "%load_ext sql\n"
   ]
  },
  {
   "cell_type": "code",
   "execution_count": 7,
   "id": "2843f865-b5a0-41b3-91da-837871734c39",
   "metadata": {},
   "outputs": [
    {
     "name": "stdout",
     "output_type": "stream",
     "text": [
      "Traceback (most recent call last):\n",
      "  File \"C:\\Users\\User\\Desktop\\PYTHON\\.venv\\lib\\site-packages\\sqlalchemy\\engine\\base.py\", line 146, in __init__\n",
      "    self._dbapi_connection = engine.raw_connection()\n",
      "  File \"C:\\Users\\User\\Desktop\\PYTHON\\.venv\\lib\\site-packages\\sqlalchemy\\engine\\base.py\", line 3298, in raw_connection\n",
      "    return self.pool.connect()\n",
      "  File \"C:\\Users\\User\\Desktop\\PYTHON\\.venv\\lib\\site-packages\\sqlalchemy\\pool\\base.py\", line 449, in connect\n",
      "    return _ConnectionFairy._checkout(self)\n",
      "  File \"C:\\Users\\User\\Desktop\\PYTHON\\.venv\\lib\\site-packages\\sqlalchemy\\pool\\base.py\", line 1263, in _checkout\n",
      "    fairy = _ConnectionRecord.checkout(pool)\n",
      "  File \"C:\\Users\\User\\Desktop\\PYTHON\\.venv\\lib\\site-packages\\sqlalchemy\\pool\\base.py\", line 712, in checkout\n",
      "    rec = pool._do_get()\n",
      "  File \"C:\\Users\\User\\Desktop\\PYTHON\\.venv\\lib\\site-packages\\sqlalchemy\\pool\\impl.py\", line 179, in _do_get\n",
      "    with util.safe_reraise():\n",
      "  File \"C:\\Users\\User\\Desktop\\PYTHON\\.venv\\lib\\site-packages\\sqlalchemy\\util\\langhelpers.py\", line 146, in __exit__\n",
      "    raise exc_value.with_traceback(exc_tb)\n",
      "  File \"C:\\Users\\User\\Desktop\\PYTHON\\.venv\\lib\\site-packages\\sqlalchemy\\pool\\impl.py\", line 177, in _do_get\n",
      "    return self._create_connection()\n",
      "  File \"C:\\Users\\User\\Desktop\\PYTHON\\.venv\\lib\\site-packages\\sqlalchemy\\pool\\base.py\", line 390, in _create_connection\n",
      "    return _ConnectionRecord(self)\n",
      "  File \"C:\\Users\\User\\Desktop\\PYTHON\\.venv\\lib\\site-packages\\sqlalchemy\\pool\\base.py\", line 674, in __init__\n",
      "    self.__connect()\n",
      "  File \"C:\\Users\\User\\Desktop\\PYTHON\\.venv\\lib\\site-packages\\sqlalchemy\\pool\\base.py\", line 900, in __connect\n",
      "    with util.safe_reraise():\n",
      "  File \"C:\\Users\\User\\Desktop\\PYTHON\\.venv\\lib\\site-packages\\sqlalchemy\\util\\langhelpers.py\", line 146, in __exit__\n",
      "    raise exc_value.with_traceback(exc_tb)\n",
      "  File \"C:\\Users\\User\\Desktop\\PYTHON\\.venv\\lib\\site-packages\\sqlalchemy\\pool\\base.py\", line 896, in __connect\n",
      "    self.dbapi_connection = connection = pool._invoke_creator(self)\n",
      "  File \"C:\\Users\\User\\Desktop\\PYTHON\\.venv\\lib\\site-packages\\sqlalchemy\\engine\\create.py\", line 646, in connect\n",
      "    return dialect.connect(*cargs, **cparams)\n",
      "  File \"C:\\Users\\User\\Desktop\\PYTHON\\.venv\\lib\\site-packages\\sqlalchemy\\engine\\default.py\", line 622, in connect\n",
      "    return self.loaded_dbapi.connect(*cargs, **cparams)\n",
      "sqlite3.OperationalError: unable to open database file\n",
      "\n",
      "The above exception was the direct cause of the following exception:\n",
      "\n",
      "Traceback (most recent call last):\n",
      "  File \"C:\\Users\\User\\Desktop\\PYTHON\\.venv\\lib\\site-packages\\sql\\magic.py\", line 196, in execute\n",
      "    conn = sql.connection.Connection.set(\n",
      "  File \"C:\\Users\\User\\Desktop\\PYTHON\\.venv\\lib\\site-packages\\sql\\connection.py\", line 70, in set\n",
      "    cls.current = existing or Connection(descriptor, connect_args, creator)\n",
      "  File \"C:\\Users\\User\\Desktop\\PYTHON\\.venv\\lib\\site-packages\\sql\\connection.py\", line 55, in __init__\n",
      "    self.internal_connection = engine.connect()\n",
      "  File \"C:\\Users\\User\\Desktop\\PYTHON\\.venv\\lib\\site-packages\\sqlalchemy\\engine\\base.py\", line 3274, in connect\n",
      "    return self._connection_cls(self)\n",
      "  File \"C:\\Users\\User\\Desktop\\PYTHON\\.venv\\lib\\site-packages\\sqlalchemy\\engine\\base.py\", line 148, in __init__\n",
      "    Connection._handle_dbapi_exception_noconnection(\n",
      "  File \"C:\\Users\\User\\Desktop\\PYTHON\\.venv\\lib\\site-packages\\sqlalchemy\\engine\\base.py\", line 2439, in _handle_dbapi_exception_noconnection\n",
      "    raise sqlalchemy_exception.with_traceback(exc_info[2]) from e\n",
      "  File \"C:\\Users\\User\\Desktop\\PYTHON\\.venv\\lib\\site-packages\\sqlalchemy\\engine\\base.py\", line 146, in __init__\n",
      "    self._dbapi_connection = engine.raw_connection()\n",
      "  File \"C:\\Users\\User\\Desktop\\PYTHON\\.venv\\lib\\site-packages\\sqlalchemy\\engine\\base.py\", line 3298, in raw_connection\n",
      "    return self.pool.connect()\n",
      "  File \"C:\\Users\\User\\Desktop\\PYTHON\\.venv\\lib\\site-packages\\sqlalchemy\\pool\\base.py\", line 449, in connect\n",
      "    return _ConnectionFairy._checkout(self)\n",
      "  File \"C:\\Users\\User\\Desktop\\PYTHON\\.venv\\lib\\site-packages\\sqlalchemy\\pool\\base.py\", line 1263, in _checkout\n",
      "    fairy = _ConnectionRecord.checkout(pool)\n",
      "  File \"C:\\Users\\User\\Desktop\\PYTHON\\.venv\\lib\\site-packages\\sqlalchemy\\pool\\base.py\", line 712, in checkout\n",
      "    rec = pool._do_get()\n",
      "  File \"C:\\Users\\User\\Desktop\\PYTHON\\.venv\\lib\\site-packages\\sqlalchemy\\pool\\impl.py\", line 179, in _do_get\n",
      "    with util.safe_reraise():\n",
      "  File \"C:\\Users\\User\\Desktop\\PYTHON\\.venv\\lib\\site-packages\\sqlalchemy\\util\\langhelpers.py\", line 146, in __exit__\n",
      "    raise exc_value.with_traceback(exc_tb)\n",
      "  File \"C:\\Users\\User\\Desktop\\PYTHON\\.venv\\lib\\site-packages\\sqlalchemy\\pool\\impl.py\", line 177, in _do_get\n",
      "    return self._create_connection()\n",
      "  File \"C:\\Users\\User\\Desktop\\PYTHON\\.venv\\lib\\site-packages\\sqlalchemy\\pool\\base.py\", line 390, in _create_connection\n",
      "    return _ConnectionRecord(self)\n",
      "  File \"C:\\Users\\User\\Desktop\\PYTHON\\.venv\\lib\\site-packages\\sqlalchemy\\pool\\base.py\", line 674, in __init__\n",
      "    self.__connect()\n",
      "  File \"C:\\Users\\User\\Desktop\\PYTHON\\.venv\\lib\\site-packages\\sqlalchemy\\pool\\base.py\", line 900, in __connect\n",
      "    with util.safe_reraise():\n",
      "  File \"C:\\Users\\User\\Desktop\\PYTHON\\.venv\\lib\\site-packages\\sqlalchemy\\util\\langhelpers.py\", line 146, in __exit__\n",
      "    raise exc_value.with_traceback(exc_tb)\n",
      "  File \"C:\\Users\\User\\Desktop\\PYTHON\\.venv\\lib\\site-packages\\sqlalchemy\\pool\\base.py\", line 896, in __connect\n",
      "    self.dbapi_connection = connection = pool._invoke_creator(self)\n",
      "  File \"C:\\Users\\User\\Desktop\\PYTHON\\.venv\\lib\\site-packages\\sqlalchemy\\engine\\create.py\", line 646, in connect\n",
      "    return dialect.connect(*cargs, **cparams)\n",
      "  File \"C:\\Users\\User\\Desktop\\PYTHON\\.venv\\lib\\site-packages\\sqlalchemy\\engine\\default.py\", line 622, in connect\n",
      "    return self.loaded_dbapi.connect(*cargs, **cparams)\n",
      "sqlalchemy.exc.OperationalError: (sqlite3.OperationalError) unable to open database file\n",
      "(Background on this error at: https://sqlalche.me/e/20/e3q8)\n",
      "\n",
      "Connection info needed in SQLAlchemy format, example:\n",
      "               postgresql://username:password@hostname/dbname\n",
      "               or an existing connection: dict_keys(['sqlite:///C:/Users/User/Desktop/PYTHON/Pamoka'])\n"
     ]
    }
   ],
   "source": [
    "%sql sqlite:///\"C:/Users/User/Desktop/PYTHON/Pamoka 21 Darbas su SQLAlchemy ir Python/mokykla.db\""
   ]
  },
  {
   "cell_type": "code",
   "execution_count": null,
   "id": "30ea01cb-3afd-44bf-b38d-45612af1da44",
   "metadata": {},
   "outputs": [],
   "source": []
  }
 ],
 "metadata": {
  "kernelspec": {
   "display_name": "Python 3 (ipykernel)",
   "language": "python",
   "name": "python3"
  },
  "language_info": {
   "codemirror_mode": {
    "name": "ipython",
    "version": 3
   },
   "file_extension": ".py",
   "mimetype": "text/x-python",
   "name": "python",
   "nbconvert_exporter": "python",
   "pygments_lexer": "ipython3",
   "version": "3.10.11"
  }
 },
 "nbformat": 4,
 "nbformat_minor": 5
}
